Workbook

Sheet 00_README
A1: 골든 데이터셋 작업 시트 v1.0 — plan-B (내 문장 고쳐주기 튜터)
A2: 2026-09-07 · 근거: 골든 데이터 샘플 B README.md · 업로드된 샘플 7파일
A4: ■ 이 시트가 v0.2와 다른 이유
A5: v0.2는 plan-A(단어 학습 RAG, PRD 6.1) 기준이었다. plan-B는 검색 대상 자체가 다르다.
A6: plan-A: 단어·문장 조각을 검색 → 문제 생성 / plan-B: 규칙 설명 조각을 검색 → 문장 첨삭
A7: 컬럼도 파일 구성도 겹치지 않으므로 v0.2를 고치지 않고 새로 만들었다. 두 시트는 별개다.
A9: ■ 시트 = 납품 파일 (README 우선순위 순)
A10: 01_rules → rules.jsonl ★ RAG 검색 대상. 여기가 제일 중요하다
A11: 02_eval → eval.csv ★ 평가셋
A12: 03_units → units.csv
A13: 04_patterns → patterns.csv
A14: 05_words → words.csv
... A53: ■ 목표량 대비 진행률
B54: 시트 | C54: 현재 | D54: 목표 | E54: 남음
B55: 01_rules | C55: =COUNTA('01_rules'!$A$2:$A$40) -> 38 | D55: 25 | E55: =MAX(0,D55-C55) -> 0
B56: 02_eval | C56: =COUNTA('02_eval'!$A$2:$A$45) -> 44 | D56: 30 | E56: =MAX(0,D56-C56) -> 0
B57: 03_units | C57: =COUNTA('03_units'!$B$2:$B$31) -> 20 | D57: 3 | E57: =MAX(0,D57-C57) -> 0
B58: 04_patterns | C58: =COUNTA('04_patterns'!$A$2:$A$401) -> 400 | D58: 20 | E58: =MAX(0,D58-C58) -> 0
B59: 05_words | C59: =COUNTA('05_words'!$A$2:$A$601) -> 401 | D59: 40 | E59: =MAX(0,D59-C59) -> 0
B60: 06_errors | C60: =COUNTA('06_errors'!$A$2:$A$401) -> 400 | D60: 40 | E60: =MAX(0,D60-C60) -> 0
B61: 07_faq | C61: =COUNTA('07_faq'!$A$2:$A$40) -> 39 | D61: 30 | E61: =MAX(0,D61-C61) -> 0
A63: ■ 내보내기
A64: 각 시트의 파란 컬럼 범위만 선택 → 새 시트에 복사 → CSV(UTF-8) 저장.
A65: jsonl 대상 시트(01·06·07)는 CSV 로 뽑은 뒤 변환 스크립트로 JSONL 을 만든다(개발 담당).
A66: 작업용·검사 컬럼을 함께 내보내면 파서가 깨지므로 범위를 반드시 확인한다.
A68: ■ 작업 순서 (README 우선순위)
A69: 1단계 01_rules 25개 + 02_eval 30개 → 여기까지만 있어도 RAG 검색 실험을 시작할 수 있다.
A70: 2단계 03_units 3개 · 04_patterns 20개 · 05_words 40개 → 화면에 붙일 데이터.
A71: 3단계 06_errors 40개 · 07_faq 30개 → 규칙 연습과 물어보기 챗.
A73: ■ rules text 를 쓸 때
A74: 학생이 실제로 쓸 법한 영어 단어 + 맞는 예 2개 + 틀린 예 1개 + 한국어 설명을 한 덩어리로.
A75: 검색은 이 text 로만 이뤄지므로, 학생 문장에 나올 단어가 text 안에 들어 있어야 걸린다.
A77: ■ faq 를 쓸 때
... A80: answer 는 초등 3학년 말투 2~3문장. 여기 적힌 것 밖의 내용은 챗이 말하지 않는다.

Sheet 01_rules
A1: id | B1: type | C1: unit | D1: text | E1: short | F1: examples (;구분) | G1: wrong_example | H1: 생성방법 | I1: 검수상태 | J1: 검수자 | K1: 비고 | L1: chk_id중복 | M1: chk_text길이 | N1: units.csv상 소속 | O1: chk_unit
A2: R-01 | B2: 형용사+be동사 | C2: Unit01 | D2: 형용사(성격·기분을 나타내는 말) 앞에는 반드시 be동사(am/is/are)가 와야 해요. I am sorry. She is polite. be동사 없이 형용사만 쓰면 안 돼요. 틀린 예: I sorry. | E2: 형용사 앞엔 be동사 | F2: I am sorry.;She is very polite. | G2: I sorry. | H2: AI 생성(단어세트 연계) | I2: 미검수 | L2: =IF(A2="","",IF(COUNTIF($A$2:$A$39,A2)>1,"중복","")) | M2: =IF(D2="","",IF(OR(LEN(D2)<80,LEN(D2)>200),LEN(D2),"")) | N2: =IF(A2="","",IFERROR(INDEX('03_units'!$B$2:$B$21,MATCH("*"&A2&"*",'03_units'!$F$2:$F$21,0)),"미참조")) -> Unit01 | O2: =IF(A2="","",IF(OR(C2="ALL",C2=N2),"","unit 불일치"))
A3: R-02 | B3: 인사말 문장부호 | C3: Unit01 | D3: 인사말 뒤에 부르는 사람 이름이 오면 쉼표(,)를 쓰고, 인사말 문장은 느낌표(!)로 마무리해요. Hello, Tom! Good morning! 쉼표나 느낌표를 빼면 어색해요. 틀린 예: Hello Tom. | E3: 인사말 뒤 쉼표·느낌표 | F3: Hello, Tom!;Good morning! | G3: Hello Tom. | H3: AI 생성(단어세트 연계) | I3: 미검수 | L3: =IF(A3="","",IF(COUNTIF($A$2:$A$39,A3)>1,"중복","")) | M3: =IF(D3="","",IF(OR(LEN(D3)<80,LEN(D3)>200),LEN(D3),"")) | N3: =IF(A3="","",IFERROR(INDEX('03_units'!$B$2:$B$21,MATCH("*"&A3&"*",'03_units'!$F$2:$F$21,0)),"미참조")) -> Unit01 | O3: =IF(A3="","",IF(OR(C3="ALL",C3=N3),"","unit 불일치"))
A4: R-03 | B4: 소유격 | C4: Unit02 | D4: 누구의 것인지 말할 때 이름 뒤에 's를 붙이거나 my/his/her 같은 소유격을 써요. This is Tom's book. She is my sister. 's나 소유격을 빼면 안 돼요. 틀린 예: This is Tom book. | E4: 누구 것? 's / my | F4: This is Tom's book.;She is my sister. | G4: This is Tom book. | H4: AI 생성(단어세트 연계) | I4: 미검수 | L4: =IF(A4="","",IF(COUNTIF($A$2:$A$39,A4)>1,"중복","")) | M4: =IF(D4="","",IF(OR(LEN(D4)<80,LEN(D4)>200),LEN(D4),"")) | N4: =IF(A4="","",IFERROR(INDEX('03_units'!$B$2:$B$21,MATCH("*"&A4&"*",'03_units'!$F$2:$F$21,0)),"미참조")) -> Unit02 | O4: =IF(A4="","",IF(OR(C4="ALL",C4=N4),"","unit 불일치"))
A5: R-04 | B5: This·These 소개구문 | C5: Unit02 | D5: 한 사람이나 물건을 소개할 땐 This is를, 여러 명이면 These are를 써요. This is my mom. These are my grandparents. is/are를 반대로 쓰면 틀려요. 틀린 예: This are my mom. | E5: 한 명 This is, 여럿 These are | F5: This is my mom.;These are my grandparents. | G5: This are my mom. | H5: AI 생성(단어세트 연계) | I5: 미검수 | L5: =IF(A5="","",IF(COUNTIF($A$2:$A$39,A5)>1,"중복","")) | M5: =IF(D5="","",IF(OR(LEN(D5)<80,LEN(D5)>200),LEN(D5),"")) | N5: =IF(A5="","",IFERROR(INDEX('03_units'!$B$2:$B$21,MATCH("*"&A5&"*",'03_units'!$F$2:$F$21,0)),"미참조")) -> Unit02 | O5: =IF(A5="","",IF(OR(C5="ALL",C5=N5),"","unit 불일치"))
A6: R-05 | B6: There is·are 구문 | C6: Unit03 | D6: 무엇이 있다고 말할 때 하나면 There is, 여러 개면 There are를 써요. There is a book on the desk. There are many students. is/are를 반대로 쓰면 틀려요. 틀린 예: There is many students. | E6: 하나 There is, 여럿 There are | F6: There is a book on the desk.;There are many students. | G6: There is many students. | H6: AI 생성(단어세트 연계) | I6: 미검수 | L6: =IF(A6="","",IF(COUNTIF($A$2:$A$39,A6)>1,"중복","")) | M6: =IF(D6="","",IF(OR(LEN(D6)<80,LEN(D6)>200),LEN(D6),"")) | N6: =IF(A6="","",IFERROR(INDEX('03_units'!$B$2:$B$21,MATCH("*"&A6&"*",'03_units'!$F$2:$F$21,0)),"미참조")) -> Unit03 | O6: =IF(A6="","",IF(OR(C6="ALL",C6=N6),"","unit 불일치"))
A7: R-06 | B7: 동사+목적어 어순 | C7: Unit03 | D7: 영어 문장은 주어+동사+목적어 순서로 써요. I read a book. She writes a letter. 목적어를 동사 앞에 쓰면 안 돼요. 틀린 예: I a book read. | E7: 주어+동사+목적어 순서 | F7: I read a book.;She writes a letter. | G7: I a book read. | H7: AI 생성(단어세트 연계) | I7: 미검수 | L7: =IF(A7="","",IF(COUNTIF($A$2:$A$39,A7)>1,"중복","")) | M7: =IF(D7="","",IF(OR(LEN(D7)<80,LEN(D7)>200),LEN(D7),"")) | N7: =IF(A7="","",IFERROR(INDEX('03_units'!$B$2:$B$21,MATCH("*"&A7&"*",'03_units'!$F$2:$F$21,0)),"미참조")) -> Unit03 | O7: =IF(A7="","",IF(OR(C7="ALL",C7=N7),"","unit 불일치"))
A8: R-07 | B8: can+동사원형 | C8: Unit04 | D8: 할 수 있는 것을 말할 때 can 뒤에는 동사원형을 그대로 써요. The rabbit can jump. Birds can fly. can 뒤에 -s나 -ing를 붙이면 안 돼요. 틀린 예: The rabbit can jumps. | E8: can 뒤엔 동사원형 | F8: The rabbit can jump.;Birds can fly. | G8: The rabbit can jumps. | H8: AI 생성(단어세트 연계) | I8: 미검수 | L8: =IF(A8="","",IF(COUNTIF($A$2:$A$39,A8)>1,"중복","")) | M8: =IF(D8="","",IF(OR(LEN(D8)<80,LEN(D8)>200),LEN(D8),"")) | N8: =IF(A8="","",IFERROR(INDEX('03_units'!$B$2:$B$21,MATCH("*"&A8&"*",'03_units'!$F$2:$F$21,0)),"미참조")) -> Unit04 | O8: =IF(A8="","",IF(OR(C8="ALL",C8=N8),"","unit 불일치"))
A9: R-08 | B9: This·These 단수복수 일치 | C9: Unit04 | D9: 가리키는 것이 하나면 This, 여러 개면 These를 쓰고 명사도 복수형(-s)으로 맞춰요. This lion is big. These lions are big. This에 복수명사를 쓰면 안 돼요. 틀린 예: This lions is big. | E9: This+단수, These+복수 | F9: This lion is big.;These lions are big. | G9: This lions is big. | H9: AI 생성(단어세트 연계) | I9: 미검수 | L9: =IF(A9="","",IF(COUNTIF($A$2:$A$39,A9)>1,"중복","")) | M9: =IF(D9="","",IF(OR(LEN(D9)<80,LEN(D9)>200),LEN(D9),"")) | N9: =IF(A9="","",IFERROR(INDEX('03_units'!$B$2:$B$21,MATCH("*"&A9&"*",'03_units'!$F$2:$F$21,0)),"미참조")) -> Unit04 | O9: =IF(A9="","",IF(OR(C9="ALL",C9=N9),"","unit 불일치"))
A10: R-09 | B10: 셀 수 없는 명사 | C10: Unit05 | D10: 물이나 밥처럼 셀 수 없는 것은 many 대신 much나 some을 써요. I have much rice. I want some water. many를 쓰면 안 돼요. 틀린 예: I have many rice. | E10: 셀 수 없으면 much/some | F10: I have much rice.;I want some water. | G10: I have many rice. | H10: AI 생성(단어세트 연계) | I10: 미검수 | L10: =IF(A10="","",IF(COUNTIF($A$2:$A$39,A10)>1,"중복","")) | M10: =IF(D10="","",IF(OR(LEN(D10)<80,LEN(D10)>200),LEN(D10),"")) | N10: =IF(A10="","",IFERROR(INDEX('03_units'!$B$2:$B$21,MATCH("*"&A10&"*",'03_units'!$F$2:$F$21,0)),"미참조")) -> Unit05 | O10: =IF(A10="","",IF(OR(C10="ALL",C10=N10),"","unit 불일치"))
A11: R-10 | B11: want+명사 | C11: Unit05 | D11: 원하는 것을 말할 때 want 뒤에 명사를 바로 써요. I want a pizza. She wants some bread. 명사 앞에 to를 붙이면 안 돼요. 틀린 예: I want to a pizza. | E11: want 뒤엔 명사 바로 | F11: I want a pizza.;She wants some bread. | G11: I want to a pizza. | H11: AI 생성(단어세트 연계) | I11: 미검수 | L11: =IF(A11="","",IF(COUNTIF($A$2:$A$39,A11)>1,"중복","")) | M11: =IF(D11="","",IF(OR(LEN(D11)<80,LEN(D11)>200),LEN(D11),"")) | N11: =IF(A11="","",IFERROR(INDEX('03_units'!$B$2:$B$21,MATCH("*"&A11&"*",'03_units'!$F$2:$F$21,0)),"미참조")) -> Unit05 | O11: =IF(A11="","",IF(OR(C11="ALL",C11=N11),"","unit 불일치"))
A12: R-11 | B12: 형용사+명사 어순 | C12: Unit06 | D12: 색깔이나 모양을 나타내는 형용사는 명사 앞에 와요. a red apple, a big house. 명사 뒤에 쓰면 안 돼요. 틀린 예: I have an apple red. | E12: 형용사는 명사 앞에 | F12: I have a red apple.;She has a big house. | G12: I have an apple red. | H12: AI 생성(단어세트 연계) | I12: 미검수 | L12: =IF(A12="","",IF(COUNTIF($A$2:$A$39,A12)>1,"중복","")) | M12: =IF(D12="","",IF(OR(LEN(D12)<80,LEN(D12)>200),LEN(D12),"")) | N12: =IF(A12="","",IFERROR(INDEX('03_units'!$B$2:$B$21,MATCH("*"&A12&"*",'03_units'!$F$2:$F$21,0)),"미참조")) -> Unit06 | O12: =IF(A12="","",IF(OR(C12="ALL",C12=N12),"","unit 불일치"))
A13: R-12 | B13: 숫자+복수명사 일치 | C13: Unit07 | D13: 둘 이상의 숫자 뒤에는 명사를 복수형(-s)으로 써요. two apples, five books. one 뒤에는 단수를 써요. 틀린 예: I have two apple. | E13: 숫자 2 이상+복수형 | F13: I have two apples.;She has five books. | G13: I have two apple. | H13: AI 생성(단어세트 연계) | I13: 미검수 | L13: =IF(A13="","",IF(COUNTIF($A$2:$A$39,A13)>1,"중복","")) | M13: =IF(D13="","",IF(OR(LEN(D13)<80,LEN(D13)>200),LEN(D13),"")) | N13: =IF(A13="","",IFERROR(INDEX('03_units'!$B$2:$B$21,MATCH("*"&A13&"*",'03_units'!$F$2:$F$21,0)),"미참조")) -> Unit07 | O13: =IF(A13="","",IF(OR(C13="ALL",C13=N13),"","unit 불일치"))
... A39: R-38 | B39: 관사 | C39: ALL | D39: 셀 수 있는 것 하나를 처음 말할 때는 앞에 a를 붙여요. a banana, a sandwich. 없이 말하면 어색해요. 틀린 예: I want banana. | E39: 하나면 앞에 a | F39: I want a banana.;She has a sandwich. | G39: I want banana. | H39: 샘플 B | I39: 미검수 | L39: =IF(A39="","",IF(COUNTIF($A$2:$A$39,A39)>1,"중복","")) | M39: =IF(D39="","",IF(OR(LEN(D39)<80,LEN(D39)>200),LEN(D39),"")) | N39: =IF(A39="","",IFERROR(INDEX('03_units'!$B$2:$B$21,MATCH("*"&A39&"*",'03_units'!$F$2:$F$21,0)),"미참조")) -> Unit01 | O39: =IF(A39="","",IF(OR(C39="ALL",C39=N39),"","unit 불일치"))
L40: =IF(A40="","",IF(COUNTIF($A$2:$A$41,A40)>1,"중복","")) | M40: =IF(D40="","",IF(OR(LEN(D40)<80,LEN(D40)>200),LEN(D40),"")) | N40: =IF(A40="","",IFERROR(INDEX('03_units'!$B$2:$B$7,MATCH("*"&A40&"*",'03_units'!$F$2:$F$7,0)),"미참조")) | O40: =IF(A40="","",IF(OR(C40="ALL",C40=N40),"","unit 불일치"))
L41: =IF(A41="","",IF(COUNTIF($A$2:$A$41,A41)>1,"중복","")) | M41: =IF(D41="","",IF(OR(LEN(D41)<80,LEN(D41)>200),LEN(D41),"")) | N41: =IF(A41="","",IFERROR(INDEX('03_units'!$B$2:$B$7,MATCH("*"&A41&"*",'03_units'!$F$2:$F$7,0)),"미참조")) | O41: =IF(A41="","",IF(OR(C41="ALL",C41=N41),"","unit 불일치"))
A43: ※ A~G열이 rules.jsonl 납품 컬럼. examples 는 ; 로 구분해 한 칸에 적으면 변환 스크립트가 배열로 만든다. 목표 38개(기존 기초 문법 8개 + Unit01~20 확장 세트 전용 30개). chk_text길이는 80~200자를 벗어난 글자 수를 보여준다 — 짧으면 검색이 안 걸리고 길면 조각이 흐려진다. chk_unit 이 뜨는 행은 rules 의 unit 과 units.csv 의 rule_ids 가 어긋난다는 뜻이다(현재 R-33).

Sheet 02_eval
A1: text | B1: expected_rule_id | C1: note | D1: 작성자 | E1: 검수상태 | F1: chk_rule존재 | G1: chk_교재중복
A2: I play with my dog yesterday. | B2: R-31 | C2: 과거시제 · 새 문장 (rules·errors와 겹치지 않음) | D2: 샘플 B | E2: 미검수 | F2: =IF(B2="","",IF(OR(B2="NONE",COUNTIF('01_rules'!$A$2:$A$39,B2)>0),"","rule 없음")) | G2: =IF(A2="","",IF(OR(COUNTIF('01_rules'!$G$2:$G$39,A2)>0,COUNTIF('06_errors'!$D$2:$D$401,A2)>0),"교재와 중복!",""))
A3: My sister like cats. | B3: R-32 | C3: 3인칭단수 | D3: 샘플 B | E3: 미검수 | F3: =IF(B3="","",IF(OR(B3="NONE",COUNTIF('01_rules'!$A$2:$A$39,B3)>0),"","rule 없음")) | G3: =IF(A3="","",IF(OR(COUNTIF('01_rules'!$G$2:$G$39,A3)>0,COUNTIF('06_errors'!$D$2:$D$401,A3)>0),"교재와 중복!",""))
A4: There are three bird in the tree. | B4: R-33 | C4: 명사복수형 | D4: 샘플 B | E4: 미검수 | F4: =IF(B4="","",IF(OR(B4="NONE",COUNTIF('01_rules'!$A$2:$A$39,B4)>0),"","rule 없음")) | G4: =IF(A4="","",IF(OR(COUNTIF('01_rules'!$G$2:$G$39,A4)>0,COUNTIF('06_errors'!$D$2:$D$401,A4)>0),"교재와 중복!",""))
A5: I ate a orange. | B5: R-34 | C5: 관사 an | D5: 샘플 B | E5: 미검수 | F5: =IF(B5="","",IF(OR(B5="NONE",COUNTIF('01_rules'!$A$2:$A$39,B5)>0),"","rule 없음")) | G5: =IF(A5="","",IF(OR(COUNTIF('01_rules'!$G$2:$G$39,A5)>0,COUNTIF('06_errors'!$D$2:$D$401,A5)>0),"교재와 중복!",""))
A6: She is eat lunch now. | B6: R-35 | C6: 현재진행형 | D6: 샘플 B | E6: 미검수 | F6: =IF(B6="","",IF(OR(B6="NONE",COUNTIF('01_rules'!$A$2:$A$39,B6)>0),"","rule 없음")) | G6: =IF(A6="","",IF(OR(COUNTIF('01_rules'!$G$2:$G$39,A6)>0,COUNTIF('06_errors'!$D$2:$D$401,A6)>0),"교재와 중복!",""))
A7: They is my friends. | B7: R-36 | C7: be동사일치 | D7: 샘플 B | E7: 미검수 | F7: =IF(B7="","",IF(OR(B7="NONE",COUNTIF('01_rules'!$A$2:$A$39,B7)>0),"","rule 없음")) | G7: =IF(A7="","",IF(OR(COUNTIF('01_rules'!$G$2:$G$39,A7)>0,COUNTIF('06_errors'!$D$2:$D$401,A7)>0),"교재와 중복!",""))
A8: We are at the park yesterday. | B8: R-37 | C8: 과거의 be동사 | D8: 샘플 B | E8: 미검수 | F8: =IF(B8="","",IF(OR(B8="NONE",COUNTIF('01_rules'!$A$2:$A$39,B8)>0),"","rule 없음")) | G8: =IF(A8="","",IF(OR(COUNTIF('01_rules'!$G$2:$G$39,A8)>0,COUNTIF('06_errors'!$D$2:$D$401,A8)>0),"교재와 중복!",""))
A9: I have dog. | B9: R-38 | C9: 관사 a | D9: 샘플 B | E9: 미검수 | F9: =IF(B9="","",IF(OR(B9="NONE",COUNTIF('01_rules'!$A$2:$A$39,B9)>0),"","rule 없음")) | G9: =IF(A9="","",IF(OR(COUNTIF('01_rules'!$G$2:$G$39,A9)>0,COUNTIF('06_errors'!$D$2:$D$401,A9)>0),"교재와 중복!",""))
A10: I saw a big lion at the zoo. | B10: NONE | C10: 정상 문장 (오탐 측정) | D10: 샘플 B | E10: 미검수 | F10: =IF(B10="","",IF(OR(B10="NONE",COUNTIF('01_rules'!$A$2:$A$39,B10)>0),"","rule 없음")) | G10: =IF(A10="","",IF(OR(COUNTIF('01_rules'!$G$2:$G$39,A10)>0,COUNTIF('06_errors'!$D$2:$D$401,A10)>0),"교재와 중복!",""))
A11: She likes bananas. | B11: NONE | C11: 정상 문장 | D11: 샘플 B | E11: 미검수 | F11: =IF(B11="","",IF(OR(B11="NONE",COUNTIF('01_rules'!$A$2:$A$39,B11)>0),"","rule 없음")) | G11: =IF(A11="","",IF(OR(COUNTIF('01_rules'!$G$2:$G$39,A11)>0,COUNTIF('06_errors'!$D$2:$D$401,A11)>0),"교재와 중복!",""))
A12: He tired after school. | B12: R-01 | C12: 형용사+be동사 (be동사 없이 형용사만) | D12: AI 생성 | E12: 미검수 | F12: =IF(B12="","",IF(OR(B12="NONE",COUNTIF('01_rules'!$A$2:$A$39,B12)>0),"","rule 없음")) | G12: =IF(A12="","",IF(OR(COUNTIF('01_rules'!$G$2:$G$39,A12)>0,COUNTIF('06_errors'!$D$2:$D$401,A12)>0),"교재와 중복!",""))
A13: This is Sam brother. | B13: R-03 | C13: 소유격 's 빠짐 | D13: AI 생성 | E13: 미검수 | F13: =IF(B13="","",IF(OR(B13="NONE",COUNTIF('01_rules'!$A$2:$A$39,B13)>0),"","rule 없음")) | G13: =IF(A13="","",IF(OR(COUNTIF('01_rules'!$G$2:$G$39,A13)>0,COUNTIF('06_errors'!$D$2:$D$401,A13)>0),"교재와 중복!",""))
... A73: The girls are playing in the park. | B73: NONE | C73: 정상 문장 | D73: AI 생성 | E73: 미검수 | F73: =IF(B73="","",IF(OR(B73="NONE",COUNTIF('01_rules'!$A$2:$A$39,B73)>0),"","rule 없음")) | G73: =IF(A73="","",IF(OR(COUNTIF('01_rules'!$G$2:$G$39,A73)>0,COUNTIF('06_errors'!$D$2:$D$401,A73)>0),"교재와 중복!",""))
A76: ※ A~C열이 eval.csv 납품 컬럼. 목표 70문항 이상 (현재 72문항)이며 그중 5개는 expected_rule_id 를 NONE 으로 둔 정상 문장이다 (틀린 데가 없는데 규칙을 찾아내는 오탐을 잡기 위한 문항). chk_교재중복 은 README 의 핵심 규칙을 검사한다 — eval 의 text 가 rules 의 wrong_example 이나 errors 의 error 와 글자 그대로 같으면 그 문항은 실력이 아니라 암기를 측정하게 된다. 걸리면 문장을 새로 지어야 한다.

Sheet 03_units
A1: level | B1: unit | C1: title | D1: mission | E1: hint_words (;구분) | F1: rule_ids (;구분) | G1: 검수상태 | H1: 비고
A2: 3 | B2: Unit01 | C2: Greetings (인사) | D2: 친구를 만나거나 헤어질 때 하는 인사말을 영어로 말해봐요 | E2: hello;hi;bye;morning;night | F2: R-32;R-38;R-01;R-02 | G2: 미검수 | H2: 400단어 세트(주제 20개, 학년 혼합 3~6, 세부 학년은 05_words.level 참고)
A3: 3 | B3: Unit02 | C3: Family (가족) | D3: 우리 가족을 영어로 소개해봐요 | E3: mom;dad;sister;brother;baby | F3: R-34;R-38;R-03;R-04 | G3: 미검수 | H3: 400단어 세트(주제 20개, 학년 혼합 3~6, 세부 학년은 05_words.level 참고)
A4: 3 | B4: Unit03 | C4: School (학교) | D4: 학교에서 쓰는 물건과 사람을 영어로 말해봐요 | E4: book;pencil;desk;chair;teacher | F4: R-34;R-38;R-05;R-06 | G4: 미검수 | H4: 400단어 세트(주제 20개, 학년 혼합 3~6, 세부 학년은 05_words.level 참고)
A5: 3 | B5: Unit04 | C5: Animals (동물) | D5: 동물원이나 주변에서 본 동물을 영어로 말해봐요 | E5: dog;cat;bird;fish;rabbit | F5: R-34;R-38;R-01;R-07;R-08 | G5: 미검수 | H5: 400단어 세트(주제 20개, 학년 혼합 3~6, 세부 학년은 05_words.level 참고)
A6: 3 | B6: Unit05 | C6: Food (음식) | D6: 좋아하는 음식을 영어로 말해봐요 | E6: apple;milk;bread;rice;egg | F6: R-34;R-38;R-09;R-10 | G6: 미검수 | H6: 400단어 세트(주제 20개, 학년 혼합 3~6, 세부 학년은 05_words.level 참고)
A7: 3 | B7: Unit06 | C7: Colors (색깔) | D7: 좋아하는 색깔을 영어로 말해봐요 | E7: red;blue;yellow;green;white | F7: R-32;R-38;R-01;R-11 | G7: 미검수 | H7: 400단어 세트(주제 20개, 학년 혼합 3~6, 세부 학년은 05_words.level 참고)
A8: 3 | B8: Unit07 | C8: Numbers (숫자) | D8: 숫자를 넣어 영어로 문장을 말해봐요 | E8: one;two;three;four;five | F8: R-38;R-12;R-13 | G8: 미검수 | H8: 400단어 세트(주제 20개, 학년 혼합 3~6, 세부 학년은 05_words.level 참고)
A9: 3 | B9: Unit08 | C9: Weather (날씨) | D9: 오늘 날씨를 영어로 말해봐요 | E9: sunny;rainy;cloudy;hot;cold | F9: R-38;R-01;R-09;R-14;R-15 | G9: 미검수 | H9: 400단어 세트(주제 20개, 학년 혼합 3~6, 세부 학년은 05_words.level 참고)
A10: 3 | B10: Unit09 | C10: Seasons (계절) | D10: 좋아하는 계절과 그 특징을 영어로 말해봐요 | E10: spring;summer;fall;winter;season | F10: R-32;R-34;R-38;R-01;R-16 | G10: 미검수 | H10: 400단어 세트(주제 20개, 학년 혼합 3~6, 세부 학년은 05_words.level 참고)
A11: 3 | B11: Unit10 | C11: Clothes (옷) | D11: 오늘 입은 옷을 영어로 말해봐요 | E11: shirt;pants;shoes;hat;socks | F11: R-34;R-36;R-38;R-17 | G11: 미검수 | H11: 400단어 세트(주제 20개, 학년 혼합 3~6, 세부 학년은 05_words.level 참고)
A12: 3 | B12: Unit11 | C12: Body (신체) | D12: 내 몸의 부분을 가리키며 영어로 말해봐요 | E12: head;hand;foot;eye;ear | F12: R-34;R-38;R-18 | G12: 미검수 | H12: 400단어 세트(주제 20개, 학년 혼합 3~6, 세부 학년은 05_words.level 참고)
A13: 3 | B13: Unit12 | C13: Sports (운동) | D13: 좋아하는 운동을 영어로 말해봐요 | E13: run;jump;swim;ball;soccer | F13: R-32;R-34;R-38;R-09;R-19 | G13: 미검수 | H13: 400단어 세트(주제 20개, 학년 혼합 3~6, 세부 학년은 05_words.level 참고)
... A21: 3 | B21: Unit20 | C21: House & Furniture (집·가구) | D21: 우리 집 방과 가구를 영어로 소개해봐요 | E21: house;room;bed;table;door | F21: R-34;R-38;R-01;R-09;R-30 | G21: 미검수 | H21: 400단어 세트(주제 20개, 학년 혼합 3~6, 세부 학년은 05_words.level 참고)
A23: ※ A~F열이 units.csv 납품 컬럼. 목표 3개. mission 은 학생에게 그대로 보여주는 말하기 과제 문장이다. rule_ids 는 이 Unit 에서 다루는 규칙 목록이며, 01_rules 의 chk_unit 검사가 이 값을 기준으로 돈다. R-32(3인칭단수, 옛 R-02) 가 U3·U4 두 곳에 있었는데 unit 을 ALL 로 통일했다. Unit01~Unit20(20개, 행 2~21)은 초등 필수 어휘 400단어(주제당 20개, 학년 혼합 3~6학년)를 다루는 별도 확장 세트다. Unit01~20 의 rule_ids 는 01_rules 의 확장 세트 전용 30개(R-01~R-30) + 기초 문법 8개(R-31~R-38, 여러 Unit에 공통 재사용) 로 채워져 있다. 01_rules 의 chk_unit 검사는 이제 U3/U4/U5(기존 예시가 제거되어 미참조) 행에만 걸린다.

Sheet 04_patterns
A1: id | B1: level | C1: unit | D1: text | E1: meaning | F1: tip | G1: rule_id | H1: 검수상태 | I1: 비고 | J1: chk_id중복 | K1: chk_rule존재 | L1: chk_unit
A2: p-0001 | B2: 3 | C2: Unit01 | D2: Hello, Tom! | E2: 톰, 안녕! | F2: 인사말 뒤 쉼표·느낌표 | G2: R-02 | H2: 미검수 | J2: =IF(A2="","",IF(COUNTIF($A$2:$A$401,A2)>1,"중복","")) | K2: =IF(G2="","",IF(COUNTIF('01_rules'!$A$2:$A$39,G2)=0,"rule 없음","")) | L2: =IF(G2="","",IF(ISNUMBER(SEARCH(G2,IFERROR(VLOOKUP(C2,'03_units'!$B$2:$F$21,5,FALSE()),""))),"","unit 불일치"))
A3: p-0002 | B3: 3 | C3: Unit01 | D3: Hi, Amy! | E3: 에이미, 안녕! | F3: 인사말 뒤 쉼표·느낌표 | G3: R-02 | H3: 미검수 | J3: =IF(A3="","",IF(COUNTIF($A$2:$A$401,A3)>1,"중복","")) | K3: =IF(G3="","",IF(COUNTIF('01_rules'!$A$2:$A$39,G3)=0,"rule 없음","")) | L3: =IF(G3="","",IF(ISNUMBER(SEARCH(G3,IFERROR(VLOOKUP(C3,'03_units'!$B$2:$F$21,5,FALSE()),""))),"","unit 불일치"))
A4: p-0003 | B4: 3 | C4: Unit01 | D4: Bye, Mike! | E4: 마이크, 잘 가! | F4: 인사말 뒤 쉼표·느낌표 | G4: R-02 | H4: 미검수 | J4: =IF(A4="","",IF(COUNTIF($A$2:$A$401,A4)>1,"중복","")) | K4: =IF(G4="","",IF(COUNTIF('01_rules'!$A$2:$A$39,G4)=0,"rule 없음","")) | L4: =IF(G4="","",IF(ISNUMBER(SEARCH(G4,IFERROR(VLOOKUP(C4,'03_units'!$B$2:$F$21,5,FALSE()),""))),"","unit 불일치"))
A5: p-0004 | B5: 3 | C5: Unit01 | D5: Good morning! | E5: 좋은 아침이에요! | F5: 인사말 뒤 쉼표·느낌표 | G5: R-02 | H5: 미검수 | J5: =IF(A5="","",IF(COUNTIF($A$2:$A$401,A5)>1,"중복","")) | K5: =IF(G5="","",IF(COUNTIF('01_rules'!$A$2:$A$39,G5)=0,"rule 없음","")) | L5: =IF(G5="","",IF(ISNUMBER(SEARCH(G5,IFERROR(VLOOKUP(C5,'03_units'!$B$2:$F$21,5,FALSE()),""))),"","unit 불일치"))
A6: p-0005 | B6: 3 | C6: Unit01 | D6: Good night! | E6: 잘 자요! | F6: 인사말 뒤 쉼표·느낌표 | G6: R-02 | H6: 미검수 | J6: =IF(A6="","",IF(COUNTIF($A$2:$A$401,A6)>1,"중복","")) | K6: =IF(G6="","",IF(COUNTIF('01_rules'!$A$2:$A$39,G6)=0,"rule 없음","")) | L6: =IF(G6="","",IF(ISNUMBER(SEARCH(G6,IFERROR(VLOOKUP(C6,'03_units'!$B$2:$F$21,5,FALSE()),""))),"","unit 불일치"))
A7: p-0006 | B7: 4 | C7: Unit01 | D7: Goodbye, Mom! | E7: 엄마, 안녕히 계세요! | F7: 인사말 뒤 쉼표·느낌표 | G7: R-02 | H7: 미검수 | J7: =IF(A7="","",IF(COUNTIF($A$2:$A$401,A7)>1,"중복","")) | K7: =IF(G7="","",IF(COUNTIF('01_rules'!$A$2:$A$39,G7)=0,"rule 없음","")) | L7: =IF(G7="","",IF(ISNUMBER(SEARCH(G7,IFERROR(VLOOKUP(C7,'03_units'!$B$2:$F$21,5,FALSE()),""))),"","unit 불일치"))
A8: p-0007 | B8: 4 | C8: Unit01 | D8: Thanks, Dad! | E8: 아빠, 고마워요! | F8: 인사말 뒤 쉼표·느낌표 | G8: R-02 | H8: 미검수 | J8: =IF(A8="","",IF(COUNTIF($A$2:$A$401,A8)>1,"중복","")) | K8: =IF(G8="","",IF(COUNTIF('01_rules'!$A$2:$A$39,G8)=0,"rule 없음","")) | L8: =IF(G8="","",IF(ISNUMBER(SEARCH(G8,IFERROR(VLOOKUP(C8,'03_units'!$B$2:$F$21,5,FALSE()),""))),"","unit 불일치"))
A9: p-0008 | B9: 4 | C9: Unit01 | D9: I am sorry. | E9: 저는 미안해요. | F9: 형용사 앞엔 be동사 | G9: R-01 | H9: 미검수 | J9: =IF(A9="","",IF(COUNTIF($A$2:$A$401,A9)>1,"중복","")) | K9: =IF(G9="","",IF(COUNTIF('01_rules'!$A$2:$A$39,G9)=0,"rule 없음","")) | L9: =IF(G9="","",IF(ISNUMBER(SEARCH(G9,IFERROR(VLOOKUP(C9,'03_units'!$B$2:$F$21,5,FALSE()),""))),"","unit 불일치"))
A10: p-0009 | B10: 4 | C10: Unit01 | D10: Please, help me! | E10: 제발, 저 좀 도와주세요! | F10: 인사말 뒤 쉼표·느낌표 | G10: R-02 | H10: 미검수 | J10: =IF(A10="","",IF(COUNTIF($A$2:$A$401,A10)>1,"중복","")) | K10: =IF(G10="","",IF(COUNTIF('01_rules'!$A$2:$A$39,G10)=0,"rule 없음","")) | L10: =IF(G10="","",IF(ISNUMBER(SEARCH(G10,IFERROR(VLOOKUP(C10,'03_units'!$B$2:$F$21,5,FALSE()),""))),"","unit 불일치"))
A11: p-0010 | B11: 4 | C11: Unit01 | D11: Welcome, everyone! | E11: 여러분, 환영해요! | F11: 인사말 뒤 쉼표·느낌표 | G11: R-02 | H11: 미검수 | J11: =IF(A11="","",IF(COUNTIF($A$2:$A$401,A11)>1,"중복","")) | K11: =IF(G11="","",IF(COUNTIF('01_rules'!$A$2:$A$39,G11)=0,"rule 없음","")) | L11: =IF(G11="","",IF(ISNUMBER(SEARCH(G11,IFERROR(VLOOKUP(C11,'03_units'!$B$2:$F$21,5,FALSE()),""))),"","unit 불일치"))
A12: p-0011 | B12: 5 | C12: Unit01 | D12: She greets her teacher every morning. | E12: 그녀는 매일 아침 선생님께 인사해요. | F12: he/she/it 주어면 동사에 -s | G12: R-32 | H12: 미검수 | J12: =IF(A12="","",IF(COUNTIF($A$2:$A$401,A12)>1,"중복","")) | K12: =IF(G12="","",IF(COUNTIF('01_rules'!$A$2:$A$39,G12)=0,"rule 없음","")) | L12: =IF(G12="","",IF(ISNUMBER(SEARCH(G12,IFERROR(VLOOKUP(C12,'03_units'!$B$2:$F$21,5,FALSE()),""))),"","unit 불일치"))
A13: p-0012 | B13: 5 | C13: Unit01 | D13: She introduces her new friend to the class. | E13: 그녀는 반 친구들에게 새 친구를 소개해요. | F13: he/she/it 주어면 동사에 -s | G13: R-32 | H13: 미검수 | J13: =IF(A13="","",IF(COUNTIF($A$2:$A$401,A13)>1,"중복","")) | K13: =IF(G13="","",IF(COUNTIF('01_rules'!$A$2:$A$39,G13)=0,"rule 없음","")) | L13: =IF(G13="","",IF(ISNUMBER(SEARCH(G13,IFERROR(VLOOKUP(C13,'03_units'!$B$2:$F$21,5,FALSE()),""))),"","unit 불일치"))
... A401: p-0400 | B401: 6 | C401: Unit20 | D401: Their new apartment is spacious. | E401: 그들의 새 아파트는 넓어요. | F401: 형용사 앞엔 be동사 | G401: R-01 | H401: 미검수 | J401: =IF(A401="","",IF(COUNTIF($A$2:$A$401,A401)>1,"중복","")) | K401: =IF(G401="","",IF(COUNTIF('01_rules'!$A$2:$A$39,G401)=0,"rule 없음","")) | L401: =IF(G401="","",IF(ISNUMBER(SEARCH(G401,IFERROR(VLOOKUP(C401,'03_units'!$B$2:$F$21,5,FALSE()),""))),"","unit 불일치"))
A404: ※ A~G열이 patterns.csv 납품 컬럼. 목표 400개(Unit01~20 확장 세트, 단어당 1문장). 기존 U3~U5용 예시 7개는 정리 과정에서 제거함. tip 은 01_rules 의 short 와 같은 문구를 쓰는 것이 좋다 — 패턴 카드와 규칙 설명이 다른 말을 하면 학생이 헷갈린다. chk_unit 은 이 패턴의 rule_id 가 해당 Unit 의 rule_ids 안에 있는지 본다.

Sheet 05_words
A1: id | B1: level | C1: unit | D1: word | E1: meaning | F1: example | G1: ncic | H1: yle_level | I1: 생성방법 | J1: 검수상태 | K1: 비고 | L1: chk_id중복 | M1: word_length
A2: w-0001 | B2: 3 | C2: Unit01 | D2: hello | E2: 안녕 | F2: Hello, Tom! | I2: AI 생성(주제별 큐레이션) | J2: 미검수 | L2: =IF(A2="","",IF(COUNTIF($A$2:$A$401,A2)>1,"중복","")) | M2: =IF(D2="","",LEN(D2)) -> 5
A3: w-0002 | B3: 3 | C3: Unit01 | D3: hi | E3: 안녕 | F3: Hi, Amy! | I3: AI 생성(주제별 큐레이션) | J3: 미검수 | L3: =IF(A3="","",IF(COUNTIF($A$2:$A$401,A3)>1,"중복","")) | M3: =IF(D3="","",LEN(D3)) -> 2
A4: w-0003 | B4: 3 | C4: Unit01 | D4: bye | E4: 안녕(헤어질 때) | F4: Bye, see you! | I4: AI 생성(주제별 큐레이션) | J4: 미검수 | L4: =IF(A4="","",IF(COUNTIF($A$2:$A$401,A4)>1,"중복","")) | M4: =IF(D4="","",LEN(D4)) -> 3
A5: w-0004 | B5: 3 | C5: Unit01 | D5: morning | E5: 아침 | F5: Good morning! | I5: AI 생성(주제별 큐레이션) | J5: 미검수 | L5: =IF(A5="","",IF(COUNTIF($A$2:$A$401,A5)>1,"중복","")) | M5: =IF(D5="","",LEN(D5)) -> 7
A6: w-0005 | B6: 3 | C6: Unit01 | D6: night | E6: 밤 | F6: Good night! | I6: AI 생성(주제별 큐레이션) | J6: 미검수 | L6: =IF(A6="","",IF(COUNTIF($A$2:$A$401,A6)>1,"중복","")) | M6: =IF(D6="","",LEN(D6)) -> 5
A7: w-0006 | B7: 4 | C7: Unit01 | D7: goodbye | E7: 잘 가 | F7: Goodbye, Mom! | I7: AI 생성(주제별 큐레이션) | J7: 미검수 | L7: =IF(A7="","",IF(COUNTIF($A$2:$A$401,A7)>1,"중복","")) | M7: =IF(D7="","",LEN(D7)) -> 7
A8: w-0007 | B8: 4 | C8: Unit01 | D8: thanks | E8: 고마워 | F8: Thanks a lot! | I8: AI 생성(주제별 큐레이션) | J8: 미검수 | L8: =IF(A8="","",IF(COUNTIF($A$2:$A$401,A8)>1,"중복","")) | M8: =IF(D8="","",LEN(D8)) -> 6
A9: w-0008 | B9: 4 | C9: Unit01 | D9: sorry | E9: 미안해 | F9: I am sorry. | I9: AI 생성(주제별 큐레이션) | J9: 미검수 | L9: =IF(A9="","",IF(COUNTIF($A$2:$A$401,A9)>1,"중복","")) | M9: =IF(D9="","",LEN(D9)) -> 5
A10: w-0009 | B10: 4 | C10: Unit01 | D10: please | E10: 부탁해요 | F10: Please help me. | I10: AI 생성(주제별 큐레이션) | J10: 미검수 | L10: =IF(A10="","",IF(COUNTIF($A$2:$A$401,A10)>1,"중복","")) | M10: =IF(D10="","",LEN(D10)) -> 6
A11: w-0010 | B11: 4 | C11: Unit01 | D11: welcome | E11: 환영하다 | F11: Welcome to my house. | I11: AI 생성(주제별 큐레이션) | J11: 미검수 | L11: =IF(A11="","",IF(COUNTIF($A$2:$A$401,A11)>1,"중복","")) | M11: =IF(D11="","",LEN(D11)) -> 7
A12: w-0011 | B12: 5 | C12: Unit01 | D12: greet | E12: 인사하다 | F12: I greet my teacher every morning. | I12: AI 생성(주제별 큐레이션) | J12: 미검수 | L12: =IF(A12="","",IF(COUNTIF($A$2:$A$401,A12)>1,"중복","")) | M12: =IF(D12="","",LEN(D12)) -> 5
A13: w-0012 | B13: 5 | C13: Unit01 | D13: introduce | E13: 소개하다 | F13: Let me introduce my friend. | I13: AI 생성(주제별 큐레이션) | J13: 미검수 | L13: =IF(A13="","",IF(COUNTIF($A$2:$A$401,A13)>1,"중복","")) | M13: =IF(D13="","",LEN(D13)) -> 9
... A401: w-0400 | B401: 6 | C401: Unit20 | D401: spacious | E401: 넓은 | F401: Their new apartment is very spacious. | I401: AI 생성(주제별 큐레이션) | J401: 미검수 | L401: =IF(A401="","",IF(COUNTIF($A$2:$A$401,A401)>1,"중복","")) | M401: =IF(D401="","",LEN(D401)) -> 8
A403: ※ A~F열이 words.csv 납품 컬럼. 목표 40개. ncic · yle_level 은 작업용이며 초3 난이도 대조용이다. 빈 칸은 아직 원본과 대조하지 않았다는 뜻이다(추측으로 채우지 말 것). plan-B 는 규칙 학습이 중심이라 Starters 기준을 그대로 적용할지는 팀 판단이 필요하다 — 00_README 참고. w-0001~w-0400(400개, 행 2~401)은 Unit01~Unit20 확장 세트의 단어다(주제 20개 x 20단어, 학년 혼합 3~6). ncic·yle_level 은 미검수 상태로 비워 두었다(추측으로 채우지 않음). chk_id중복 범위는 전체 행($A$2:$A$401)으로 넓혔다.

Sheet 06_errors
A1: id | B1: unit | C1: rule_id | D1: error | E1: correct | F1: target | G1: fix | H1: distractors (;구분) | I1: 검수상태 | J1: 비고 | K1: chk_id중복 | L1: chk_rule존재 | M1: chk_동일문장 | N1: chk_보기수
A2: E-0001 | B2: Unit01 | C2: R-02 | D2: Hello Tom. | E2: Hello, Tom! | F2: Hello Tom | G2: Hello, Tom! | H2: —;—;— | I2: 미검수 | K2: =IF(A2="","",IF(COUNTIF($A$2:$A$401,A2)>1,"중복","")) | L2: =IF(C2="","",IF(COUNTIF('01_rules'!$A$2:$A$39,C2)=0,"rule 없음","")) | M2: =IF(D2="","",IF(D2=E2,"error=correct","")) | N2: =IF(H2="","",IF(LEN(H2)-LEN(SUBSTITUTE(H2,";",""))<>2,"보기 3개 아님",""))
A3: E-0002 | B3: Unit01 | C3: R-02 | D3: Hi Amy. | E3: Hi, Amy! | F3: Hi Amy | G3: Hi, Amy! | H3: —;—;— | I3: 미검수 | K3: =IF(A3="","",IF(COUNTIF($A$2:$A$401,A3)>1,"중복","")) | L3: =IF(C3="","",IF(COUNTIF('01_rules'!$A$2:$A$39,C3)=0,"rule 없음","")) | M3: =IF(D3="","",IF(D3=E3,"error=correct","")) | N3: =IF(H3="","",IF(LEN(H3)-LEN(SUBSTITUTE(H3,";",""))<>2,"보기 3개 아님",""))
A4: E-0003 | B4: Unit01 | C4: R-02 | D4: Bye Mike. | E4: Bye, Mike! | F4: Bye Mike | G4: Bye, Mike! | H4: —;—;— | I4: 미검수 | K4: =IF(A4="","",IF(COUNTIF($A$2:$A$401,A4)>1,"중복","")) | L4: =IF(C4="","",IF(COUNTIF('01_rules'!$A$2:$A$39,C4)=0,"rule 없음","")) | M4: =IF(D4="","",IF(D4=E4,"error=correct","")) | N4: =IF(H4="","",IF(LEN(H4)-LEN(SUBSTITUTE(H4,";",""))<>2,"보기 3개 아님",""))
A5: E-0004 | B5: Unit01 | C5: R-02 | D5: Good morning. | E5: Good morning! | F5: morning. | G5: morning! | H5: —;—;— | I5: 미검수 | K5: =IF(A5="","",IF(COUNTIF($A$2:$A$401,A5)>1,"중복","")) | L5: =IF(C5="","",IF(COUNTIF('01_rules'!$A$2:$A$39,C5)=0,"rule 없음","")) | M5: =IF(D5="","",IF(D5=E5,"error=correct","")) | N5: =IF(H5="","",IF(LEN(H5)-LEN(SUBSTITUTE(H5,";",""))<>2,"보기 3개 아님",""))
A6: E-0005 | B6: Unit01 | C6: R-02 | D6: Good night. | E6: Good night! | F6: night. | G6: night! | H6: —;—;— | I6: 미검수 | K6: =IF(A6="","",IF(COUNTIF($A$2:$A$401,A6)>1,"중복","")) | L6: =IF(C6="","",IF(COUNTIF('01_rules'!$A$2:$A$39,C6)=0,"rule 없음","")) | M6: =IF(D6="","",IF(D6=E6,"error=correct","")) | N6: =IF(H6="","",IF(LEN(H6)-LEN(SUBSTITUTE(H6,";",""))<>2,"보기 3개 아님",""))
A7: E-0006 | B7: Unit01 | C7: R-02 | D7: Goodbye Mom. | E7: Goodbye, Mom! | F7: Goodbye Mom | G7: Goodbye, Mom! | H7: —;—;— | I7: 미검수 | K7: =IF(A7="","",IF(COUNTIF($A$2:$A$401,A7)>1,"중복","")) | L7: =IF(C7="","",IF(COUNTIF('01_rules'!$A$2:$A$39,C7)=0,"rule 없음","")) | M7: =IF(D7="","",IF(D7=E7,"error=correct","")) | N7: =IF(H7="","",IF(LEN(H7)-LEN(SUBSTITUTE(H7,";",""))<>2,"보기 3개 아님",""))
A8: E-0007 | B8: Unit01 | C8: R-02 | D8: Thanks Dad. | E8: Thanks, Dad! | F8: Thanks Dad | G8: Thanks, Dad! | H8: —;—;— | I8: 미검수 | K8: =IF(A8="","",IF(COUNTIF($A$2:$A$401,A8)>1,"중복","")) | L8: =IF(C8="","",IF(COUNTIF('01_rules'!$A$2:$A$39,C8)=0,"rule 없음","")) | M8: =IF(D8="","",IF(D8=E8,"error=correct","")) | N8: =IF(H8="","",IF(LEN(H8)-LEN(SUBSTITUTE(H8,";",""))<>2,"보기 3개 아님",""))
A9: E-0008 | B9: Unit01 | C9: R-01 | D9: I sorry. | E9: I am sorry. | F9: I sorry | G9: I am sorry | H9: —;—;— | I9: 미검수 | K9: =IF(A9="","",IF(COUNTIF($A$2:$A$401,A9)>1,"중복","")) | L9: =IF(C9="","",IF(COUNTIF('01_rules'!$A$2:$A$39,C9)=0,"rule 없음","")) | M9: =IF(D9="","",IF(D9=E9,"error=correct","")) | N9: =IF(H9="","",IF(LEN(H9)-LEN(SUBSTITUTE(H9,";",""))<>2,"보기 3개 아님",""))
A10: E-0009 | B10: Unit01 | C10: R-02 | D10: Please help me. | E10: Please, help me! | F10: Please help me. | G10: Please, help me! | H10: —;—;— | I10: 미검수 | K10: =IF(A10="","",IF(COUNTIF($A$2:$A$401,A10)>1,"중복","")) | L10: =IF(C10="","",IF(COUNTIF('01_rules'!$A$2:$A$39,C10)=0,"rule 없음","")) | M10: =IF(D10="","",IF(D10=E10,"error=correct","")) | N10: =IF(H10="","",IF(LEN(H10)-LEN(SUBSTITUTE(H10,";",""))<>2,"보기 3개 아님",""))
A11: E-0010 | B11: Unit01 | C11: R-02 | D11: Welcome everyone. | E11: Welcome, everyone! | F11: Welcome everyone | G11: Welcome, everyone! | H11: —;—;— | I11: 미검수 | K11: =IF(A11="","",IF(COUNTIF($A$2:$A$401,A11)>1,"중복","")) | L11: =IF(C11="","",IF(COUNTIF('01_rules'!$A$2:$A$39,C11)=0,"rule 없음","")) | M11: =IF(D11="","",IF(D11=E11,"error=correct","")) | N11: =IF(H11="","",IF(LEN(H11)-LEN(SUBSTITUTE(H11,";",""))<>2,"보기 3개 아님",""))
A12: E-0011 | B12: Unit01 | C12: R-32 | D12: She greet her teacher every morning. | E12: She greets her teacher every morning. | F12: greet | G12: greets | H12: greeting;greeted;to greet | I12: 미검수 | K12: =IF(A12="","",IF(COUNTIF($A$2:$A$401,A12)>1,"중복","")) | L12: =IF(C12="","",IF(COUNTIF('01_rules'!$A$2:$A$39,C12)=0,"rule 없음","")) | M12: =IF(D12="","",IF(D12=E12,"error=correct","")) | N12: =IF(H12="","",IF(LEN(H12)-LEN(SUBSTITUTE(H12,";",""))<>2,"보기 3개 아님",""))
A13: E-0012 | B13: Unit01 | C13: R-32 | D13: She introduce her new friend to the class. | E13: She introduces her new friend to the class. | F13: introduce | G13: introduces | H13: introduceing;introduced;to introduce | I13: 미검수 | K13: =IF(A13="","",IF(COUNTIF($A$2:$A$401,A13)>1,"중복","")) | L13: =IF(C13="","",IF(COUNTIF('01_rules'!$A$2:$A$39,C13)=0,"rule 없음","")) | M13: =IF(D13="","",IF(D13=E13,"error=correct","")) | N13: =IF(H13="","",IF(LEN(H13)-LEN(SUBSTITUTE(H13,";",""))<>2,"보기 3개 아님",""))
... A401: E-0400 | B401: Unit20 | C401: R-01 | D401: Their new apartment spacious. | E401: Their new apartment is spacious. | F401: apartment spacious | G401: apartment is spacious | H401: —;—;— | I401: 미검수 | K401: =IF(A401="","",IF(COUNTIF($A$2:$A$401,A401)>1,"중복","")) | L401: =IF(C401="","",IF(COUNTIF('01_rules'!$A$2:$A$39,C401)=0,"rule 없음","")) | M401: =IF(D401="","",IF(D401=E401,"error=correct","")) | N401: =IF(H401="","",IF(LEN(H401)-LEN(SUBSTITUTE(H401,";",""))<>2,"보기 3개 아님",""))
A404: ※ A~H열이 errors.jsonl 납품 컬럼. 목표 400개(Unit01~20 확장 세트, 단어당 1문장). 기존 U3~U5용 예시 8개는 정리 과정에서 제거함. distractors 는 ; 로 3개를 구분해 적는다 — chk_보기수 가 세미콜론 개수로 검사한다. target 은 학생이 고쳐야 할 원래 낱말, fix 는 정답이다. 두 값이 error·correct 문장 안에 실제로 들어 있는지는 사람이 확인한다(수식으로 잡지 않는다).

Sheet 07_faq
A1: id | B1: unit | C1: question | D1: variants (;구분) | E1: answer | F1: rule_ids (;구분) | G1: example | H1: 질문유형 | I1: 검수상태 | J1: 비고 | K1: chk_id중복 | L1: chk_variants수 | M1: chk_rule존재
A2: F-01 | B2: U3 | C2: 왜 went예요? | D2: go 과거가 뭐예요;갔다를 영어로 뭐라고 해요;went가 무슨 뜻이에요 | E2: go의 과거형은 규칙 없이 went로 바뀌어요. 이런 동사를 불규칙 동사라고 해요. see는 saw, eat는 ate가 돼요. | F2: R-31 | G2: I went to the zoo yesterday. | H2: 규칙 질문 | I2: 미검수 | K2: =IF(A2="","",IF(COUNTIF($A$2:$A$75,A2)>1,"중복","")) | L2: =IF(D2="","",IF(LEN(D2)-LEN(SUBSTITUTE(D2,";",""))+1<3,"3개 미만","")) | M2: =IF(F2="","",IF(COUNTIF('01_rules'!$A$2:$A$39,LEFT(F2,4))=0,"rule 없음",""))
A3: F-02 | B3: U3 | C3: saw는 무슨 뜻이에요? | D3: saw가 뭐예요;봤다를 영어로;see 과거형 | E3: saw는 see(보다)의 과거형이에요. '봤다'라는 뜻이에요. | F3: R-31 | G3: I saw a rabbit. | H3: 단어 뜻 질문 | I3: 미검수 | K3: =IF(A3="","",IF(COUNTIF($A$2:$A$75,A3)>1,"중복","")) | L3: =IF(D3="","",IF(LEN(D3)-LEN(SUBSTITUTE(D3,";",""))+1<3,"3개 미만","")) | M3: =IF(F3="","",IF(COUNTIF('01_rules'!$A$2:$A$39,LEFT(F3,4))=0,"rule 없음",""))
A4: F-03 | B4: ALL | C4: a랑 an 차이가 뭐예요? | D4: 언제 an 써요;an elephant 왜 an이에요;a elephant 틀렸어요? | E4: 다음 단어의 첫 소리가 a, e, i, o, u면 an, 아니면 a예요. 글자가 아니라 소리예요. an elephant, a rabbit. | F4: R-34;R-38 | G4: I saw an elephant. | H4: 규칙 질문 | I4: 미검수 | K4: =IF(A4="","",IF(COUNTIF($A$2:$A$75,A4)>1,"중복","")) | L4: =IF(D4="","",IF(LEN(D4)-LEN(SUBSTITUTE(D4,";",""))+1<3,"3개 미만","")) | M4: =IF(F4="","",IF(COUNTIF('01_rules'!$A$2:$A$39,LEFT(F4,4))=0,"rule 없음",""))
A5: F-04 | B5: ALL | C5: yesterday 대신 뭘 쓸 수 있어요? | D5: 지난주는 영어로;어제 말고 다른 말;과거 표현 뭐 있어요 | E5: last week(지난주), last night(어젯밤), two days ago(이틀 전)처럼 지난 때를 나타내는 말이면 다 과거형 동사와 같이 써요. | F5: R-31 | G5: We ate pizza last night. | H5: 다른 예문 요청 | I5: 미검수 | K5: =IF(A5="","",IF(COUNTIF($A$2:$A$75,A5)>1,"중복","")) | L5: =IF(D5="","",IF(LEN(D5)-LEN(SUBSTITUTE(D5,";",""))+1<3,"3개 미만","")) | M5: =IF(F5="","",IF(COUNTIF('01_rules'!$A$2:$A$39,LEFT(F5,4))=0,"rule 없음",""))
A6: F-05 | B6: U5 | C6: 왜 -s를 붙여요? | D6: eats 왜 s 붙어요;3인칭 단수가 뭐예요;she like 틀렸어요? | E6: he, she, it처럼 한 명이나 한 마리가 지금 하는 일이면 동사 끝에 -s를 붙여요. I나 you, they는 안 붙여요. | F6: R-32 | G6: The lion eats meat. | H6: 규칙 질문 | I6: 미검수 | K6: =IF(A6="","",IF(COUNTIF($A$2:$A$75,A6)>1,"중복","")) | L6: =IF(D6="","",IF(LEN(D6)-LEN(SUBSTITUTE(D6,";",""))+1<3,"3개 미만","")) | M6: =IF(F6="","",IF(COUNTIF('01_rules'!$A$2:$A$39,LEFT(F6,4))=0,"rule 없음",""))
A7: F-06 | B7: U3 | C7: 동물원이 영어로 뭐예요? | D7: zoo가 뭐예요;동물원 영어;zoo 뜻이 뭐예요 | E7: zoo예요. We went to the zoo. = 우리는 동물원에 갔어요. | G7: We went to the zoo. | H7: 단어 뜻 질문 | I7: 미검수 | J7: unit 이 U5 인데 R-02 는 U5 의 rule_ids 에 없음 — 확인 필요 | K7: =IF(A7="","",IF(COUNTIF($A$2:$A$75,A7)>1,"중복","")) | L7: =IF(D7="","",IF(LEN(D7)-LEN(SUBSTITUTE(D7,";",""))+1<3,"3개 미만","")) | M7: =IF(F7="","",IF(COUNTIF('01_rules'!$A$2:$A$39,LEFT(F7,4))=0,"rule 없음",""))
A8: F-07 | B8: Unit01 | C8: 왜 I am sorry에는 am이 있어요? | D8: 형용사 앞에 뭐가 와요;am 없이 I sorry 하면 안 돼요?;be동사가 왜 필요해요 | E8: 성격이나 기분을 나타내는 형용사(sorry, polite 등) 앞에는 반드시 am/is/are 같은 be동사가 와야 해요. | F8: R-01 | G8: I am sorry. | H8: 규칙 질문 | I8: 미검수 | K8: =IF(A8="","",IF(COUNTIF($A$2:$A$75,A8)>1,"중복","")) | L8: =IF(D8="","",IF(LEN(D8)-LEN(SUBSTITUTE(D8,";",""))+1<3,"3개 미만","")) | M8: =IF(F8="","",IF(COUNTIF('01_rules'!$A$2:$A$39,LEFT(F8,4))=0,"rule 없음",""))
A9: F-08 | B9: Unit02 | C9: Tom's book에서 's는 뭐예요? | D9: 's가 무슨 뜻이에요;누구 것인지 어떻게 말해요;소유격이 뭐예요 | E9: 이름 뒤에 's를 붙이면 '~의 것'이라는 뜻이 돼요. Tom's book = 톰의 책. | F9: R-03 | G9: This is Tom's book. | H9: 규칙 질문 | I9: 미검수 | K9: =IF(A9="","",IF(COUNTIF($A$2:$A$75,A9)>1,"중복","")) | L9: =IF(D9="","",IF(LEN(D9)-LEN(SUBSTITUTE(D9,";",""))+1<3,"3개 미만","")) | M9: =IF(F9="","",IF(COUNTIF('01_rules'!$A$2:$A$39,LEFT(F9,4))=0,"rule 없음",""))
A10: F-09 | B10: Unit03 | C10: There is와 There are는 언제 써요? | D10: 하나일 때랑 여럿일 때 뭐가 달라요;There is many 이렇게 써도 돼요?;is/are 어떻게 골라요 | E10: 뒤에 오는 것이 하나면 There is, 여러 개면 There are를 써요. 뒤의 명사 수에 맞춰야 해요. | F10: R-05 | G10: There are many students. | H10: 규칙 질문 | I10: 미검수 | K10: =IF(A10="","",IF(COUNTIF($A$2:$A$75,A10)>1,"중복","")) | L10: =IF(D10="","",IF(LEN(D10)-LEN(SUBSTITUTE(D10,";",""))+1<3,"3개 미만","")) | M10: =IF(F10="","",IF(COUNTIF('01_rules'!$A$2:$A$39,LEFT(F10,4))=0,"rule 없음",""))
A11: F-10 | B11: Unit04 | C11: can 뒤에 왜 동사에 -s를 안 붙여요? | D11: can jumps 왜 틀려요;can 다음엔 뭐가 와요;can runs 이거 맞아요? | E11: can 뒤에는 주어가 무엇이든 항상 동사원형을 그대로 써요. -s나 -ing를 붙이면 안 돼요. | F11: R-07 | G11: The rabbit can jump high. | H11: 규칙 질문 | I11: 미검수 | K11: =IF(A11="","",IF(COUNTIF($A$2:$A$75,A11)>1,"중복","")) | L11: =IF(D11="","",IF(LEN(D11)-LEN(SUBSTITUTE(D11,";",""))+1<3,"3개 미만","")) | M11: =IF(F11="","",IF(COUNTIF('01_rules'!$A$2:$A$39,LEFT(F11,4))=0,"rule 없음",""))
A12: F-11 | B12: Unit05 | C12: 물이나 밥은 왜 many를 못 써요? | D12: 셀 수 없는 명사가 뭐예요;much랑 many 차이가 뭐예요;water many 이거 왜 틀려요 | E12: 물, 밥처럼 개수를 셀 수 없는 것은 many 대신 much나 some을 써요. | F12: R-09 | G12: I have much rice. | H12: 규칙 질문 | I12: 미검수 | K12: =IF(A12="","",IF(COUNTIF($A$2:$A$75,A12)>1,"중복","")) | L12: =IF(D12="","",IF(LEN(D12)-LEN(SUBSTITUTE(D12,";",""))+1<3,"3개 미만","")) | M12: =IF(F12="","",IF(COUNTIF('01_rules'!$A$2:$A$39,LEFT(F12,4))=0,"rule 없음",""))
A13: F-12 | B13: Unit06 | C13: 형용사는 왜 명사 앞에 와요? | D13: red apple 순서가 왜 그래요;apple red 이렇게 쓰면 안 돼요?;색깔 말할 때 순서가 어떻게 돼요 | E13: 색깔이나 모양을 나타내는 형용사는 우리말과 반대로 명사 앞에 와요. a red apple처럼요. | F13: R-11 | G13: I have a red apple. | H13: 규칙 질문 | I13: 미검수 | K13: =IF(A13="","",IF(COUNTIF($A$2:$A$75,A13)>1,"중복","")) | L13: =IF(D13="","",IF(LEN(D13)-LEN(SUBSTITUTE(D13,";",""))+1<3,"3개 미만","")) | M13: =IF(F13="","",IF(COUNTIF('01_rules'!$A$2:$A$39,LEFT(F13,4))=0,"rule 없음",""))
A14: F-13 | B14: Unit08 | C14: 날씨 말할 때 It은 무슨 뜻이에요? | D14: It is sunny에서 It이 뭘 가리켜요;날씨는 This is로 말하면 안 돼요?;비인칭주어가 뭐예요 | E14: 날씨를 말할 때 쓰는 It은 특별한 뜻이 없는 주어예요. this나 that으로 바꿔 쓰면 안 돼요. | F14: R-14 | G14: It is sunny today. | H14: 규칙 질문 | I14: 미검수 | K14: =IF(A14="","",IF(COUNTIF($A$2:$A$75,A14)>1,"중복","")) | L14: =IF(D14="","",IF(LEN(D14)-LEN(SUBSTITUTE(D14,";",""))+1<3,"3개 미만","")) | M14: =IF(F14="","",IF(COUNTIF('01_rules'!$A$2:$A$39,LEFT(F14,4))=0,"rule 없음",""))
A15: F-14 | B15: Unit10 | C15: 지금 입고 있다는 왜 wear가 아니라 wearing이에요? | D15: wear랑 wearing 차이가 뭐예요;She wear now 이거 왜 틀려요;지금 하는 중이라는 걸 어떻게 말해요 | E15: 지금 입고 있는 중이라는 뜻은 be동사+wearing으로 말해요. wear만 쓰면 지금 하는 중이라는 뜻이 안 돼요. | F15: R-17 | G15: She is wearing a red dress. | H15: 규칙 질문 | I15: 미검수 | K15: =IF(A15="","",IF(COUNTIF($A$2:$A$75,A15)>1,"중복","")) | L15: =IF(D15="","",IF(LEN(D15)-LEN(SUBSTITUTE(D15,";",""))+1<3,"3개 미만","")) | M15: =IF(F15="","",IF(COUNTIF('01_rules'!$A$2:$A$39,LEFT(F15,4))=0,"rule 없음",""))
A16: F-15 | B16: Unit12 | C16: like 다음에는 왜 동사에 -ing를 붙여요? | D16: like swim 이거 왜 틀려요;좋아하는 걸 말할 때 동사 형태가 어떻게 돼요;like 뒤에 to를 써도 돼요? | E16: 좋아하는 활동을 말할 때 like 뒤에는 동사-ing(동명사)를 써요. 동사원형만 쓰면 어색해요. | F16: R-19 | G16: I like swimming. | H16: 규칙 질문 | I16: 미검수 | K16: =IF(A16="","",IF(COUNTIF($A$2:$A$75,A16)>1,"중복","")) | L16: =IF(D16="","",IF(LEN(D16)-LEN(SUBSTITUTE(D16,";",""))+1<3,"3개 미만","")) | M16: =IF(F16="","",IF(COUNTIF('01_rules'!$A$2:$A$39,LEFT(F16,4))=0,"rule 없음",""))
A17: F-16 | B17: Unit14 | C17: 요일 이름은 왜 항상 대문자로 써요? | D17: monday 이렇게 소문자로 쓰면 틀려요?;요일 앞에 전치사는 뭐 써요;on Monday 왜 on이에요 | E17: 요일 이름(Monday, Tuesday...)은 항상 대문자로 시작하고, 앞에는 전치사 on을 써요. | F17: R-21 | G17: I have a test on Monday. | H17: 규칙 질문 | I17: 미검수 | K17: =IF(A17="","",IF(COUNTIF($A$2:$A$75,A17)>1,"중복","")) | L17: =IF(D17="","",IF(LEN(D17)-LEN(SUBSTITUTE(D17,";",""))+1<3,"3개 미만","")) | M17: =IF(F17="","",IF(COUNTIF('01_rules'!$A$2:$A$39,LEFT(F17,4))=0,"rule 없음",""))
A18: F-17 | B18: Unit17 | C18: 장래희망 말할 때 want to be 다음에 왜 a/an이 필요해요? | D18: want to be doctor 이거 왜 틀려요;직업 앞에 관사를 꼭 써야 해요?;become이랑 want to be 뭐가 달라요 | E18: 장래희망을 말할 때 want to be 뒤에는 a나 an과 직업 이름을 같이 써요. 관사를 빼면 안 돼요. | F18: R-25 | G18: I want to be a doctor. | H18: 규칙 질문 | I18: 미검수 | K18: =IF(A18="","",IF(COUNTIF($A$2:$A$75,A18)>1,"중복","")) | L18: =IF(D18="","",IF(LEN(D18)-LEN(SUBSTITUTE(D18,";",""))+1<3,"3개 미만","")) | M18: =IF(F18="","",IF(COUNTIF('01_rules'!$A$2:$A$39,LEFT(F18,4))=0,"rule 없음",""))
A19: F-18 | B19: Unit20 | C19: in, on, under는 어떻게 구별해요? | D19: 위치전치사가 뭐예요;in the box랑 on the box 뭐가 달라요;under는 언제 써요 | E19: 안에 있으면 in, 위에 있으면 on, 아래에 있으면 under를 써요. 위치가 다르면 전치사도 달라져요. | F19: R-30 | G19: The cat is in the box. | H19: 규칙 질문 | I19: 미검수 | K19: =IF(A19="","",IF(COUNTIF($A$2:$A$75,A19)>1,"중복","")) | L19: =IF(D19="","",IF(LEN(D19)-LEN(SUBSTITUTE(D19,";",""))+1<3,"3개 미만","")) | M19: =IF(F19="","",IF(COUNTIF('01_rules'!$A$2:$A$39,LEFT(F19,4))=0,"rule 없음",""))
A20: F-19 | B20: Unit09 | C20: 계절 앞에는 왜 in을 써요? | D20: in spring 왜 in이에요;계절 앞에 on이나 at 쓰면 안 돼요?;달 앞에도 in 써요? | E20: 계절이나 달(월) 앞에는 전치사 in을 써요. on이나 at을 쓰면 안 돼요. | F20: R-16 | G20: Flowers bloom in spring. | H20: 규칙 질문 | I20: 미검수 | K20: =IF(A20="","",IF(COUNTIF($A$2:$A$75,A20)>1,"중복","")) | L20: =IF(D20="","",IF(LEN(D20)-LEN(SUBSTITUTE(D20,";",""))+1<3,"3개 미만","")) | M20: =IF(F20="","",IF(COUNTIF('01_rules'!$A$2:$A$39,LEFT(F20,4))=0,"rule 없음",""))
A21: F-20 | B21: Unit01 | C21: farewell이 무슨 뜻이에요? | D21: farewell이 뭐예요;작별 인사를 영어로;goodbye랑 farewell 차이 | E21: farewell은 '작별 인사'라는 뜻이에요. 헤어질 때 하는 인사를 가리켜요. | G21: It was a warm farewell. | H21: 단어 뜻 질문 | I21: 미검수 | K21: =IF(A21="","",IF(COUNTIF($A$2:$A$75,A21)>1,"중복","")) | L21: =IF(D21="","",IF(LEN(D21)-LEN(SUBSTITUTE(D21,";",""))+1<3,"3개 미만","")) | M21: =IF(F21="","",IF(COUNTIF('01_rules'!$A$2:$A$39,LEFT(F21,4))=0,"rule 없음",""))
A22: F-21 | B22: Unit02 | C22: ancestor가 무슨 뜻이에요? | D22: ancestor가 뭐예요;조상을 영어로;할아버지의 할아버지는 영어로 뭐예요 | E22: ancestor는 '조상'이라는 뜻이에요. 아주 오래전에 살았던 가족을 가리켜요. | G22: I have an ancestor. | H22: 단어 뜻 질문 | I22: 미검수 | K22: =IF(A22="","",IF(COUNTIF($A$2:$A$75,A22)>1,"중복","")) | L22: =IF(D22="","",IF(LEN(D22)-LEN(SUBSTITUTE(D22,";",""))+1<3,"3개 미만","")) | M22: =IF(F22="","",IF(COUNTIF('01_rules'!$A$2:$A$39,LEFT(F22,4))=0,"rule 없음",""))
A23: F-22 | B23: Unit04 | C23: ecosystem이 무슨 뜻이에요? | D23: ecosystem이 뭐예요;생태계를 영어로;동물과 식물이 사는 환경을 영어로 | E23: ecosystem은 '생태계'라는 뜻이에요. 동물, 식물, 환경이 서로 영향을 주고받는 것을 말해요. | G23: I have an ecosystem. | H23: 단어 뜻 질문 | I23: 미검수 | K23: =IF(A23="","",IF(COUNTIF($A$2:$A$75,A23)>1,"중복","")) | L23: =IF(D23="","",IF(LEN(D23)-LEN(SUBSTITUTE(D23,";",""))+1<3,"3개 미만","")) | M23: =IF(F23="","",IF(COUNTIF('01_rules'!$A$2:$A$39,LEFT(F23,4))=0,"rule 없음",""))
A24: F-23 | B24: Unit05 | C24: appetite가 무슨 뜻이에요? | D24: appetite가 뭐예요;식욕을 영어로;밥맛이 있다를 영어로 | E24: appetite는 '식욕'이라는 뜻이에요. 음식을 먹고 싶은 마음을 가리켜요. | G24: Good appetite is important. | H24: 단어 뜻 질문 | I24: 미검수 | K24: =IF(A24="","",IF(COUNTIF($A$2:$A$75,A24)>1,"중복","")) | L24: =IF(D24="","",IF(LEN(D24)-LEN(SUBSTITUTE(D24,";",""))+1<3,"3개 미만","")) | M24: =IF(F24="","",IF(COUNTIF('01_rules'!$A$2:$A$39,LEFT(F24,4))=0,"rule 없음",""))
A25: F-24 | B25: Unit12 | C25: endurance가 무슨 뜻이에요? | D25: endurance가 뭐예요;지구력을 영어로;오래 버티는 힘을 영어로 | E25: endurance는 '지구력'이라는 뜻이에요. 힘들어도 오래 버티고 계속할 수 있는 힘을 가리켜요. | G25: Running builds much endurance. | H25: 단어 뜻 질문 | I25: 미검수 | K25: =IF(A25="","",IF(COUNTIF($A$2:$A$75,A25)>1,"중복","")) | L25: =IF(D25="","",IF(LEN(D25)-LEN(SUBSTITUTE(D25,";",""))+1<3,"3개 미만","")) | M25: =IF(F25="","",IF(COUNTIF('01_rules'!$A$2:$A$39,LEFT(F25,4))=0,"rule 없음",""))
A26: F-25 | B26: Unit13 | C26: leisure가 무슨 뜻이에요? | D26: leisure가 뭐예요;여가를 영어로;쉬는 시간을 영어로 | E26: leisure는 '여가'라는 뜻이에요. 일이나 공부를 하지 않고 쉬거나 취미를 즐기는 시간을 가리켜요. | G26: He has much leisure time. | H26: 단어 뜻 질문 | I26: 미검수 | K26: =IF(A26="","",IF(COUNTIF($A$2:$A$75,A26)>1,"중복","")) | L26: =IF(D26="","",IF(LEN(D26)-LEN(SUBSTITUTE(D26,";",""))+1<3,"3개 미만","")) | M26: =IF(F26="","",IF(COUNTIF('01_rules'!$A$2:$A$39,LEFT(F26,4))=0,"rule 없음",""))
A27: F-26 | B27: Unit15 | C27: commute가 무슨 뜻이에요? | D27: commute가 뭐예요;통근을 영어로;학교나 회사에 왔다갔다 하는 걸 영어로 | E27: commute는 '통근하다'라는 뜻이에요. 집에서 학교나 회사까지 왔다갔다 다니는 것을 가리켜요. | G27: She commutes to work by subway. | H27: 단어 뜻 질문 | I27: 미검수 | K27: =IF(A27="","",IF(COUNTIF($A$2:$A$75,A27)>1,"중복","")) | L27: =IF(D27="","",IF(LEN(D27)-LEN(SUBSTITUTE(D27,";",""))+1<3,"3개 미만","")) | M27: =IF(F27="","",IF(COUNTIF('01_rules'!$A$2:$A$39,LEFT(F27,4))=0,"rule 없음",""))
A28: F-27 | B28: Unit20 | C28: spacious가 무슨 뜻이에요? | D28: spacious가 뭐예요;넓다를 영어로;big이랑 spacious 차이 | E28: spacious는 '넓은'이라는 뜻이에요. 공간이 크고 넉넉하다는 걸 나타내요. | G28: Their new apartment is spacious. | H28: 단어 뜻 질문 | I28: 미검수 | K28: =IF(A28="","",IF(COUNTIF($A$2:$A$75,A28)>1,"중복","")) | L28: =IF(D28="","",IF(LEN(D28)-LEN(SUBSTITUTE(D28,";",""))+1<3,"3개 미만","")) | M28: =IF(F28="","",IF(COUNTIF('01_rules'!$A$2:$A$39,LEFT(F28,4))=0,"rule 없음",""))
A29: F-28 | B29: Unit05 | C29: much/some 쓰는 문장 더 보여주세요 | D29: 다른 예문 알려줘요;셀 수 없는 명사 문장 더;much 쓰는 문장 또 있어요? | E29: I have much rice. I want some water. I ate much bread. He drinks much milk. | F29: R-09 | G29: I have much rice. | H29: 다른 예문 요청 | I29: 미검수 | K29: =IF(A29="","",IF(COUNTIF($A$2:$A$75,A29)>1,"중복","")) | L29: =IF(D29="","",IF(LEN(D29)-LEN(SUBSTITUTE(D29,";",""))+1<3,"3개 미만","")) | M29: =IF(F29="","",IF(COUNTIF('01_rules'!$A$2:$A$39,LEFT(F29,4))=0,"rule 없음",""))
A30: F-29 | B30: Unit12 | C30: like+동명사 문장 더 보여주세요 | D30: 다른 예문 알려줘요;like -ing 예문 더;좋아하는 것 말하는 문장 또 | E30: I like swimming. She likes playing soccer. He likes drawing. They like singing. | F30: R-19 | G30: I like swimming. | H30: 다른 예문 요청 | I30: 미검수 | K30: =IF(A30="","",IF(COUNTIF($A$2:$A$75,A30)>1,"중복","")) | L30: =IF(D30="","",IF(LEN(D30)-LEN(SUBSTITUTE(D30,";",""))+1<3,"3개 미만","")) | M30: =IF(F30="","",IF(COUNTIF('01_rules'!$A$2:$A$39,LEFT(F30,4))=0,"rule 없음",""))
A31: F-30 | B31: Unit15 | C31: by+교통수단 문장 더 보여주세요 | D31: 다른 예문 알려줘요;교통수단 예문 더;by bus 말고 다른 문장 | E31: We go to school by car. She goes home by taxi. He travels by train. They go by subway. | F31: R-23 | G31: We go to school by bus. | H31: 다른 예문 요청 | I31: 미검수 | K31: =IF(A31="","",IF(COUNTIF($A$2:$A$75,A31)>1,"중복","")) | L31: =IF(D31="","",IF(LEN(D31)-LEN(SUBSTITUTE(D31,";",""))+1<3,"3개 미만","")) | M31: =IF(F31="","",IF(COUNTIF('01_rules'!$A$2:$A$39,LEFT(F31,4))=0,"rule 없음",""))
A32: F-31 | B32: Unit18 | C32: 감정형용사+전치사 문장 더 보여주세요 | D32: 다른 예문 알려줘요;proud of 같은 예문 더;걱정하다 표현 다른 예문 | E32: She is proud of her son. He is worried about the exam. I am jealous of my friend. | F32: R-27 | G32: She is proud of you. | H32: 다른 예문 요청 | I32: 미검수 | K32: =IF(A32="","",IF(COUNTIF($A$2:$A$75,A32)>1,"중복","")) | L32: =IF(D32="","",IF(LEN(D32)-LEN(SUBSTITUTE(D32,";",""))+1<3,"3개 미만","")) | M32: =IF(F32="","",IF(COUNTIF('01_rules'!$A$2:$A$39,LEFT(F32,4))=0,"rule 없음",""))
A33: F-33 | B33: Unit01 | C33: 인사말 뒤에 쉼표는 왜 필요해요? | D33: Hello Tom 이렇게 쓰면 안 돼요?;쉼표를 빼도 돼요;느낌표는 꼭 써야 해요 | E33: 부르는 사람 이름 앞에는 쉼표(,)를 쓰고 인사말 끝에는 느낌표(!)를 써요. Hello, Tom!처럼요. | F33: R-02 | G33: Hello, Tom! | H33: 규칙 질문 | I33: 미검수 | K33: =IF(A33="","",IF(COUNTIF($A$2:$A$75,A33)>1,"중복","")) | L33: =IF(D33="","",IF(LEN(D33)-LEN(SUBSTITUTE(D33,";",""))+1<3,"3개 미만","")) | M33: =IF(F33="","",IF(COUNTIF('01_rules'!$A$2:$A$39,LEFT(F33,4))=0,"rule 없음",""))
A34: F-34 | B34: Unit02 | C34: 여러 명 소개할 땐 뭐라고 해요? | D34: These are 언제 써요;This is랑 뭐가 달라요;가족 여러 명 소개하기 | E34: 여러 명이나 여러 개를 소개할 땐 These are를 써요. This is는 한 명일 때만 써요. | F34: R-04 | G34: These are my grandparents. | H34: 규칙 질문 | I34: 미검수 | K34: =IF(A34="","",IF(COUNTIF($A$2:$A$75,A34)>1,"중복","")) | L34: =IF(D34="","",IF(LEN(D34)-LEN(SUBSTITUTE(D34,";",""))+1<3,"3개 미만","")) | M34: =IF(F34="","",IF(COUNTIF('01_rules'!$A$2:$A$39,LEFT(F34,4))=0,"rule 없음",""))
A35: F-35 | B35: Unit03 | C35: 영어 문장 순서가 헷갈려요 | D35: 주어 동사 목적어가 뭐예요;I a book read 왜 틀려요;문장 순서 어떻게 만들어요 | E35: 영어는 주어+동사+목적어 순서로 써요. 목적어를 동사 앞에 쓰면 안 돼요. | F35: R-06 | G35: I read a book. | H35: 규칙 질문 | I35: 미검수 | K35: =IF(A35="","",IF(COUNTIF($A$2:$A$75,A35)>1,"중복","")) | L35: =IF(D35="","",IF(LEN(D35)-LEN(SUBSTITUTE(D35,";",""))+1<3,"3개 미만","")) | M35: =IF(F35="","",IF(COUNTIF('01_rules'!$A$2:$A$39,LEFT(F35,4))=0,"rule 없음",""))
A36: F-36 | B36: Unit04 | C36: This랑 These 어떻게 골라요? | D36: This lion These lions 차이;하나면 뭐 써요;여러 개면 뭐 써요 | E36: 하나면 This, 여러 개면 These를 쓰고 명사도 복수형으로 맞춰요. | F36: R-08 | G36: These lions are big. | H36: 규칙 질문 | I36: 미검수 | K36: =IF(A36="","",IF(COUNTIF($A$2:$A$75,A36)>1,"중복","")) | L36: =IF(D36="","",IF(LEN(D36)-LEN(SUBSTITUTE(D36,";",""))+1<3,"3개 미만","")) | M36: =IF(F36="","",IF(COUNTIF('01_rules'!$A$2:$A$39,LEFT(F36,4))=0,"rule 없음",""))
A37: F-37 | B37: Unit05 | C37: 원하는 거 말할 때 to 붙여도 돼요? | D37: I want to a pizza 왜 틀려요;want 다음에 뭐가 와요;want to be랑 뭐가 달라요 | E37: 원하는 것(명사)을 말할 때 want 뒤에는 to 없이 바로 명사를 써요. | F37: R-10 | G37: I want a pizza. | H37: 규칙 질문 | I37: 미검수 | K37: =IF(A37="","",IF(COUNTIF($A$2:$A$75,A37)>1,"중복","")) | L37: =IF(D37="","",IF(LEN(D37)-LEN(SUBSTITUTE(D37,";",""))+1<3,"3개 미만","")) | M37: =IF(F37="","",IF(COUNTIF('01_rules'!$A$2:$A$39,LEFT(F37,4))=0,"rule 없음",""))
A38: F-38 | B38: Unit07 | C38: 숫자 뒤에는 왜 -s를 붙여요? | D38: two apple 왜 틀려요;복수형 언제 만들어요;one 뒤에도 -s 붙여요? | E38: 둘 이상의 숫자 뒤에는 명사를 복수형(-s)으로 써요. one 뒤에는 단수를 그대로 써요. | F38: R-12 | G38: I have two apples. | H38: 규칙 질문 | I38: 미검수 | K38: =IF(A38="","",IF(COUNTIF($A$2:$A$75,A38)>1,"중복","")) | L38: =IF(D38="","",IF(LEN(D38)-LEN(SUBSTITUTE(D38,";",""))+1<3,"3개 미만","")) | M38: =IF(F38="","",IF(COUNTIF('01_rules'!$A$2:$A$39,LEFT(F38,4))=0,"rule 없음",""))
A39: F-39 | B39: Unit07 | C39: 첫 번째, 두 번째 앞에 the 왜 붙여요? | D39: the first 왜 the가 있어요;서수가 뭐예요;the 빼도 돼요? | E39: 순서를 말하는 first, second 앞에는 항상 the를 붙여요. | F39: R-13 | G39: She was the first to finish. | H39: 규칙 질문 | I39: 미검수 | K39: =IF(A39="","",IF(COUNTIF($A$2:$A$75,A39)>1,"중복","")) | L39: =IF(D39="","",IF(LEN(D39)-LEN(SUBSTITUTE(D39,";",""))+1<3,"3개 미만","")) | M39: =IF(F39="","",IF(COUNTIF('01_rules'!$A$2:$A$39,LEFT(F39,4))=0,"rule 없음",""))
A40: F-40 | B40: Unit08 | C40: will 다음엔 뭐가 와요? | D40: will rains 왜 틀려요;미래 말할 때 동사 형태;will 뒤에 -ing 써도 돼요? | E40: 앞으로의 일을 말하는 will 뒤에는 항상 동사원형을 그대로 써요. | F40: R-15 | G40: It will rain tomorrow. | H40: 규칙 질문 | I40: 미검수 | K40: =IF(A40="","",IF(COUNTIF($A$2:$A$75,A40)>1,"중복","")) | L40: =IF(D40="","",IF(LEN(D40)-LEN(SUBSTITUTE(D40,";",""))+1<3,"3개 미만","")) | M40: =IF(F40="","",IF(COUNTIF('01_rules'!$A$2:$A$39,LEFT(F40,4))=0,"rule 없음",""))
...

Sheet 08_검수로그
A1: 일시 | B1: 대상 시트 | C1: 대상 id | D1: 현재 값 | E1: 제안 값 | F1: 사유 | G1: 상태 | H1: 검수자
A2: 2026-09-07 | B2: 01_rules | C2: R-03 | D2: unit = U3 | E2: unit = U4 | F2: units.csv 는 R-03 을 U4 에 배치. patterns p-0005, errors E-0005 도 U4 — rules 쪽만 U3 | G2: 발견
A3: 2026-09-07 | B3: 01_rules | C3: R-02 | D3: unit = U3 | E3: unit = ALL(?) | F3: units.csv 에서 U3·U4 두 곳이 참조. README 규칙상 여러 Unit 이면 ALL | G3: 발견
A4: 2026-09-07 | B4: 07_faq | C4: F-05 | D4: unit = U5 | E4: (미정) | F4: 근거 규칙 R-02 가 U5 의 rule_ids 에 없음 | G4: 발견
A5: 2026-09-07 | B5: 01_rules | C5: R-07 | D5: unit = ALL | E5: (미정) | F5: 어느 Unit 의 rule_ids 에도 없어 화면에 노출될 경로가 없다. eval 에는 문항이 있음 | G5: 발견
A6: 2026-09-07 | B6: 07_faq | C6: F-06 | D6: variants 2개 | E6: 3개 이상으로 보강 | F6: README 규칙은 variants 3개 이상 — 검색 적중률에 직접 영향 | G6: 발견
A7: 2026-09-07 | B7: 05_words | C7: w-0007 | D7: My teacher is kind. | E7: (미정) | F7: kind 를 형용사로 쓰면 Cambridge Flyers 등급. plan-A 샘플에서도 같은 지적 | G7: 발견
A8: 2026-09-07 | B8: 05_words | C8: w-0001, w-0002 | D8: rabbit, lion | E8: (미정) | F8: Cambridge 등급이 Movers. plan-B 에서 이 기준을 유지할지 팀 판단 필요 | G8: 보류
A29: ※ 납품하지 않는 시트다. 자동 검사에 걸린 것과 사람이 발견한 것을 모두 여기 남긴다. '제안 값'이 (미정)인 행은 아직 교체안을 정하지 않은 것이다. 팀 합의 후 채우고 상태를 '반영'으로 바꾼다.
